<?xml version="1.0" ?>
<!-- =================================================================================== -->
<!-- |    This document was autogenerated by xacro from urdf/freehicle/freehicle.xacro | -->
<!-- |    EDITING THIS FILE BY HAND IS NOT RECOMMENDED                                 | -->
<!-- =================================================================================== -->
<robot name="hivebot">
  <link name="body">
    <inertial>
      <mass value="30"/>
      <origin rpy="0 0 0" xyz="0 0 0.1016"/>
      <inertia ixx="1" ixy="0.0" ixz="0.0" iyy="1" iyz="0.0" izz="1"/>
    </inertial>
    <collision name="center_tube">
      <origin rpy="0 1.5707963 0" xyz="0 0 0"/>
      <geometry>
        <cylinder length="0.8382" radius="0.008"/>
      </geometry>
    </collision>
    <visual name="center_tube">
      <origin rpy="0 1.5707963 0" xyz="0 0 0"/>
      <geometry>
        <cylinder length="0.8382" radius="0.008"/>
      </geometry>
    </visual>
    <collision name="back_tube">
      <origin rpy="1.5707963 0 0" xyz="0.4191 0 0"/>
      <geometry>
        <cylinder length="0.4826" radius="0.008"/>
      </geometry>
    </collision>
    <visual name="back_tube">
      <origin rpy="1.5707963 0 0" xyz="0.4191 0 0"/>
      <geometry>
        <cylinder length="0.4826" radius="0.008"/>
      </geometry>
    </visual>
    <collision name="back_tube">
      <origin rpy="1.5707963 0 0" xyz="-0.4191 0 0"/>
      <geometry>
        <cylinder length="0.28" radius="0.008"/>
      </geometry>
    </collision>
    <visual name="back_tube">
      <origin rpy="1.5707963 0 0" xyz="-0.4191 0 0"/>
      <geometry>
        <cylinder length="0.28" radius="0.008"/>
      </geometry>
    </visual>
  </link>
  <link name="front_left_link">
    <inertial>
      <mass value="0.01"/>
      <origin rpy="0 0 0" xyz="0 0 0"/>
      <inertia ixx="1e-9" ixy="0.0" ixz="0.0" iyy="1e-9" iyz="0.0" izz="1e-9"/>
    </inertial>
  </link>
  <joint name="front_left_link" type="revolute">
    <parent link="body"/>
    <child link="front_left_link"/>
    <origin rpy="0 0 0" xyz="0.4191 -0.2413 0"/>
    <axis xyz="0 0 1"/>
    <limit effort="0" lower="-0.392699075" upper="0.392699075" velocity="0"/>
  </joint>
  <link name="front_right_link">
    <inertial>
      <mass value="0.01"/>
      <origin rpy="0 0 0" xyz="0 0 0"/>
      <inertia ixx="1e-9" ixy="0.0" ixz="0.0" iyy="1e-9" iyz="0.0" izz="1e-9"/>
    </inertial>
  </link>
  <joint name="front_right_link" type="revolute">
    <parent link="body"/>
    <child link="front_right_link"/>
    <origin rpy="0 0 0" xyz="0.4191 0.2413 0"/>
    <axis xyz="0 0 1"/>
    <limit effort="0" lower="-0.392699075" upper="0.392699075" velocity="0"/>
  </joint>
  <link name="wheel_front_left">
    <inertial>
      <mass value="1"/>
      <origin rpy="0 0 0" xyz="0 0 0"/>
      <inertia ixx="0.05" ixy="0" ixz="0" iyy="0.05" iyz="0" izz="0.05"/>
    </inertial>
    <collision name="collision">
      <origin rpy="0 0 0" xyz="0 0 0"/>
      <geometry>
        <cylinder length="0.05" radius="0.127"/>
      </geometry>
    </collision>
    <visual name="visual">
      <origin rpy="1.5707963 0 0" xyz="0  0  0"/>
      <geometry>
        <cylinder length="0.05" radius="0.127"/>
      </geometry>
    </visual>
  </link>
  <joint name="wheel_front_left" type="continuous">
    <parent link="front_left_link"/>
    <child link="wheel_front_left"/>
    <origin rpy="0 0 0" xyz="0 0 0"/>
    <axis xyz="0 1 0"/>
  </joint>
  <link name="wheel_front_right">
    <inertial>
      <mass value="1"/>
      <origin rpy="0 0 0" xyz="0 0 0"/>
      <inertia ixx="0.05" ixy="0" ixz="0" iyy="0.05" iyz="0" izz="0.05"/>
    </inertial>
    <collision name="collision">
      <origin rpy="0 0 0" xyz="0 0 0"/>
      <geometry>
        <cylinder length="0.05" radius="0.127"/>
      </geometry>
    </collision>
    <visual name="visual">
      <origin rpy="1.5707963 0 0" xyz="0  0  0"/>
      <geometry>
        <cylinder length="0.05" radius="0.127"/>
      </geometry>
    </visual>
  </link>
  <joint name="wheel_front_right" type="continuous">
    <parent link="front_right_link"/>
    <child link="wheel_front_right"/>
    <origin rpy="0 0 0" xyz="0 0 0"/>
    <axis xyz="0 1 0"/>
  </joint>
  <link name="wheel_back_left">
    <inertial>
      <mass value="1"/>
      <origin rpy="0 0 0" xyz="0 0 0"/>
      <inertia ixx="0.05" ixy="0" ixz="0" iyy="0.05" iyz="0" izz="0.05"/>
    </inertial>
    <collision name="collision">
      <origin rpy="0 0 0" xyz="0 0 0"/>
      <geometry>
        <cylinder length="0.05" radius="0.1016"/>
      </geometry>
    </collision>
    <visual name="visual">
      <origin rpy="1.5707963 0 0" xyz="0  0  0"/>
      <geometry>
        <cylinder length="0.05" radius="0.1016"/>
      </geometry>
    </visual>
  </link>
  <joint name="wheel_back_left" type="continuous">
    <parent link="body"/>
    <child link="wheel_back_left"/>
    <origin rpy="0 0 0" xyz="-0.4191 -0.14 0"/>
    <axis xyz="0 1 0"/>
  </joint>
  <link name="wheel_back_right">
    <inertial>
      <mass value="1"/>
      <origin rpy="0 0 0" xyz="0 0 0"/>
      <inertia ixx="0.05" ixy="0" ixz="0" iyy="0.05" iyz="0" izz="0.05"/>
    </inertial>
    <collision name="collision">
      <origin rpy="0 0 0" xyz="0 0 0"/>
      <geometry>
        <cylinder length="0.05" radius="0.1016"/>
      </geometry>
    </collision>
    <visual name="visual">
      <origin rpy="1.5707963 0 0" xyz="0  0  0"/>
      <geometry>
        <cylinder length="0.05" radius="0.1016"/>
      </geometry>
    </visual>
  </link>
  <joint name="wheel_back_right" type="continuous">
    <parent link="body"/>
    <child link="wheel_back_right"/>
    <origin rpy="0 0 0" xyz="-0.4191 0.14 0"/>
    <axis xyz="0 1 0"/>
  </joint>
</robot>
