<robot name="hive" xmlns:xacro="http://www.ros.org/wiki/xacro">
    <xacro:macro name="wheel" params="name origin radius x_offset y_offset">
        <link name="wheel_${name}">
            <inertial>
                <mass value="1"/>
                <origin rpy="0 0 0" xyz="0 0 0"/>
                <inertia ixx="0.05" ixy="0" ixz="0"
                         iyy="0.05" iyz="0"
                         izz="0.05"/>
            </inertial>
            <collision name="collision">
                <origin rpy="${PI/2} 0 0" xyz="0  0  0"/>
                <geometry>
                    <cylinder radius="${radius}" length="0.05" />
                </geometry>
            </collision>
            <visual name="visual">
                <origin rpy="${PI/2} 0 0" xyz="0  0  0"/>
                <geometry>
                    <cylinder radius="${radius}" length="0.05" />
                </geometry>
            </visual>
        </link>

        <joint name="wheel_${name}" type="continuous">
            <parent link="${origin}"/>
            <child link="wheel_${name}"/>
            <origin rpy="0 0 0" xyz="${x_offset} ${y_offset} 0"/>
            <axis xyz="0 1 0"/>
        </joint>

    </xacro:macro>
</robot>
